<?xml version="1.0" ?>
<robot name="psd_vehicle" xmlns:xacro="http://www.ros.org/wiki/xacro">

  <xacro:include filename="$(find psd_vehicle_description)/src/description/materials.xacro" />
  <xacro:include filename="$(find psd_vehicle_description)/src/description/psd_vehicle.trans" />
  <xacro:include filename="$(find psd_vehicle_description)/src/description/psd_vehicle.gazebo" />

  <link name="base_link">
    <visual>  
      <geometry>
        <box size="0.01 0.01 0.01"/>
      </geometry>
    </visual>
  </link> 

	<!-- Chassis START-->  
	<joint name="base_joint" type="fixed">
    <parent link="base_link"/> 
    <child link="chassis"/> 
  </joint> 

  <link name="chassis">
    <inertial>
      <origin xyz="-0.055282024534886974 0.006459558608433099 1.621642854614675e-05" rpy="0 0 0"/>
      <mass value="7.077984465449566"/>
      <inertia ixx="0.233109" iyy="0.053798" izz="0.264742" ixy="-0.0" iyz="-0.0" ixz="-0.0"/>
    </inertial>
    <visual>
      <origin xyz="0 0 0" rpy="0 0 0"/>
      <geometry>
        <mesh filename="package://psd_vehicle_description/src/description/meshes/base_link.stl" scale="0.001 0.001 0.001"/>
      </geometry>
      <material name="silver"/>
    </visual>
    <collision>
      <origin xyz="0 0 0" rpy="0 0 0"/>
      <geometry>
        <mesh filename="package://psd_vehicle_description/src/description/meshes/base_link.stl" scale="0.001 0.001 0.001"/>
      </geometry>
    </collision>
  </link>

  <link name="perno_FL_1">
    <inertial>
      <origin xyz="-0.000906687358749575 0.00042296243032097225 2.1642838935455414e-07" rpy="0 0 0"/>
      <mass value="0.00011097676048806171"/>
      <inertia ixx="0.0" iyy="0.0" izz="0.0" ixy="-0.0" iyz="0.0" ixz="-0.0"/>
    </inertial>
    <visual>
      <origin xyz="0.230783 -0.306869 -1.6e-05" rpy="0 0 0"/>
      <geometry>
        <mesh filename="package://psd_vehicle_description/src/description/meshes/perno_FL_1.stl" scale="0.001 0.001 0.001"/>
      </geometry>
      <material name="silver"/>
    </visual>
    <collision>
      <origin xyz="0.230783 -0.306869 -1.6e-05" rpy="0 0 0"/>
      <geometry>
        <mesh filename="package://psd_vehicle_description/src/description/meshes/perno_FL_1.stl" scale="0.001 0.001 0.001"/>
      </geometry>
    </collision>
  </link>

  <link name="tyre_FL_1">
    <inertial>
      <origin xyz="-0.03851807609484373 0.017960856816041648 2.1642854673904234e-07" rpy="0 0 0"/>
      <mass value="0.1944554118066591"/>
      <inertia ixx="0.001191" iyy="0.000933" izz="0.000861" ixy="-0.000154" iyz="0.0" ixz="0.0"/>
    </inertial>
    <visual>
      <origin xyz="0.232596 -0.307715 -1.6e-05" rpy="0 0 0"/>
      <geometry>
        <mesh filename="package://psd_vehicle_description/src/description/meshes/tyre_FL_1.stl" scale="0.001 0.001 0.001"/>
      </geometry>
      <material name="silver"/>
    </visual>
    <collision>
      <origin xyz="0.232596 -0.307715 -1.6e-05" rpy="0 0 0"/>
      <geometry>
        <mesh filename="package://psd_vehicle_description/src/description/meshes/tyre_FL_1.stl" scale="0.001 0.001 0.001"/>
      </geometry>
    </collision>
  </link>

  <link name="perno_FR_1">
    <inertial>
      <origin xyz="0.000905928215323884 -0.0004222740931605351 2.1642839664261197e-07" rpy="0 0 0"/>
      <mass value="0.0001109767604880609"/>
      <inertia ixx="0.0" iyy="0.0" izz="0.0" ixy="-0.0" iyz="-0.0" ixz="0.0"/>
    </inertial>
    <visual>
      <origin xyz="-0.120217 -0.306869 -1.6e-05" rpy="0 0 0"/>
      <geometry>
        <mesh filename="package://psd_vehicle_description/src/description/meshes/perno_FR_1.stl" scale="0.001 0.001 0.001"/>
      </geometry>
      <material name="silver"/>
    </visual>
    <collision>
      <origin xyz="-0.120217 -0.306869 -1.6e-05" rpy="0 0 0"/>
      <geometry>
        <mesh filename="package://psd_vehicle_description/src/description/meshes/perno_FR_1.stl" scale="0.001 0.001 0.001"/>
      </geometry>
    </collision>
  </link>

  <link name="tyre_FR_1">
    <inertial>
      <origin xyz="0.03851831695141855 -0.017961168478880185 2.1642854608751476e-07" rpy="0 0 0"/>
      <mass value="0.19445541180665865"/>
      <inertia ixx="0.001191" iyy="0.000933" izz="0.000861" ixy="-0.000154" iyz="-0.0" ixz="0.0"/>
    </inertial>
    <visual>
      <origin xyz="-0.122029 -0.306024 -1.6e-05" rpy="0 0 0"/>
      <geometry>
        <mesh filename="package://psd_vehicle_description/src/description/meshes/tyre_FR_1.stl" scale="0.001 0.001 0.001"/>
      </geometry>
      <material name="silver"/>
    </visual>
    <collision>
      <origin xyz="-0.122029 -0.306024 -1.6e-05" rpy="0 0 0"/>
      <geometry>
        <mesh filename="package://psd_vehicle_description/src/description/meshes/tyre_FR_1.stl" scale="0.001 0.001 0.001"/>
      </geometry>
    </collision>
  </link>

  <link name="tyre_RR_1">
    <inertial>
      <origin xyz="0.04250016447333546 3.441685788030391e-07 2.16428546438244e-07" rpy="0 0 0"/>
      <mass value="0.19445541180665948"/>
      <inertia ixx="0.001262" iyy="0.000861" izz="0.000861" ixy="-0.0" iyz="-0.0" ixz="0.0"/>
    </inertial>
    <visual>
      <origin xyz="-0.119284 0.293131 -1.6e-05" rpy="0 0 0"/>
      <geometry>
        <mesh filename="package://psd_vehicle_description/src/description/meshes/tyre_RR_1.stl" scale="0.001 0.001 0.001"/>
      </geometry>
      <material name="silver"/>
    </visual>
    <collision>
      <origin xyz="-0.119284 0.293131 -1.6e-05" rpy="0 0 0"/>
      <geometry>
        <mesh filename="package://psd_vehicle_description/src/description/meshes/tyre_RR_1.stl" scale="0.001 0.001 0.001"/>
      </geometry>
    </collision>
  </link>

  <link name="link_RL_1">
    <inertial>
      <origin xyz="-0.047944553368047954 3.441685789140614e-07 2.1642854618965338e-07" rpy="0 0 0"/>
      <mass value="0.09195911794645473"/>
      <inertia ixx="6.5e-05" iyy="0.000142" izz="0.000206" ixy="-0.0" iyz="0.0" ixz="0.0"/>
    </inertial>
    <visual>
      <origin xyz="0.095283 0.293131 -1.6e-05" rpy="0 0 0"/>
      <geometry>
        <mesh filename="package://psd_vehicle_description/src/description/meshes/link_RL_1.stl" scale="0.001 0.001 0.001"/>
      </geometry>
      <material name="silver"/>
    </visual>
    <collision>
      <origin xyz="0.095283 0.293131 -1.6e-05" rpy="0 0 0"/>
      <geometry>
        <mesh filename="package://psd_vehicle_description/src/description/meshes/link_RL_1.stl" scale="0.001 0.001 0.001"/>
      </geometry>
    </collision>
  </link>

  <link name="link_RR_1">
    <inertial>
      <origin xyz="0.04794379422462264 3.441685790250837e-07 2.1642854618632285e-07" rpy="0 0 0"/>
      <mass value="0.09195911794645475"/>
      <inertia ixx="6.5e-05" iyy="0.000142" izz="0.000206" ixy="0.0" iyz="-0.0" ixz="0.0"/>
    </inertial>
    <visual>
      <origin xyz="0.015283 0.293131 -1.6e-05" rpy="0 0 0"/>
      <geometry>
        <mesh filename="package://psd_vehicle_description/src/description/meshes/link_RR_1.stl" scale="0.001 0.001 0.001"/>
      </geometry>
      <material name="silver"/>
    </visual>
    <collision>
      <origin xyz="0.015283 0.293131 -1.6e-05" rpy="0 0 0"/>
      <geometry>
        <mesh filename="package://psd_vehicle_description/src/description/meshes/link_RR_1.stl" scale="0.001 0.001 0.001"/>
      </geometry>
    </collision>
  </link>

  <link name="tyre_RL_1">
    <inertial>
      <origin xyz="-0.04249992361676111 3.4416857908059484e-07 2.1642854653184114e-07" rpy="0 0 0"/>
      <mass value="0.19445541180665912"/>
      <inertia ixx="0.001262" iyy="0.000861" izz="0.000861" ixy="0.0" iyz="0.0" ixz="0.0"/>
    </inertial>
    <visual>
      <origin xyz="0.229851 0.293131 -1.6e-05" rpy="0 0 0"/>
      <geometry>
        <mesh filename="package://psd_vehicle_description/src/description/meshes/tyre_RL_1.stl" scale="0.001 0.001 0.001"/>
      </geometry>
      <material name="silver"/>
    </visual>
    <collision>
      <origin xyz="0.229851 0.293131 -1.6e-05" rpy="0 0 0"/>
      <geometry>
        <mesh filename="package://psd_vehicle_description/src/description/meshes/tyre_RL_1.stl" scale="0.001 0.001 0.001"/>
      </geometry>
    </collision>
  </link>

  <link name="link_FL_1">
    <inertial>
      <origin xyz="-0.04795315128569644 3.441685794691729e-07 2.1642854620519813e-07" rpy="0 0 0"/>
      <mass value="0.09196821373647668"/>
      <inertia ixx="6.5e-05" iyy="0.000142" izz="0.000206" ixy="0.0" iyz="0.0" ixz="-0.0"/>
    </inertial>
    <visual>
      <origin xyz="0.095283 -0.306869 -1.6e-05" rpy="0 0 0"/>
      <geometry>
        <mesh filename="package://psd_vehicle_description/src/description/meshes/link_FL_1.stl" scale="0.001 0.001 0.001"/>
      </geometry>
      <material name="silver"/>
    </visual>
    <collision>
      <origin xyz="0.095283 -0.306869 -1.6e-05" rpy="0 0 0"/>
      <geometry>
        <mesh filename="package://psd_vehicle_description/src/description/meshes/link_FL_1.stl" scale="0.001 0.001 0.001"/>
      </geometry>
    </collision>
  </link>

  <link name="link_FR_1">
    <inertial>
      <origin xyz="0.04795239214227047 3.441685796912175e-07 2.164285462018676e-07" rpy="0 0 0"/>
      <mass value="0.09196821373647673"/>
      <inertia ixx="6.5e-05" iyy="0.000142" izz="0.000206" ixy="-0.0" iyz="0.0" ixz="0.0"/>
    </inertial>
    <visual>
      <origin xyz="0.015283 -0.306869 -1.6e-05" rpy="0 0 0"/>
      <geometry>
        <mesh filename="package://psd_vehicle_description/src/description/meshes/link_FR_1.stl" scale="0.001 0.001 0.001"/>
      </geometry>
      <material name="silver"/>
    </visual>
    <collision>
      <origin xyz="0.015283 -0.306869 -1.6e-05" rpy="0 0 0"/>
      <geometry>
        <mesh filename="package://psd_vehicle_description/src/description/meshes/link_FR_1.stl" scale="0.001 0.001 0.001"/>
      </geometry>
    </collision>
  </link>

  <joint name="Rivoluzione_14" type="revolute">
    <origin xyz="-0.1355 0.0 0.0" rpy="0 0 0"/>
    <parent link="link_FL_1"/>
    <child link="perno_FL_1"/>
    <axis xyz="0.0 -0.0 1.0"/>
    <limit upper="0.523599" lower="-0.523599" effort="100" velocity="100"/>
  </joint>

  <joint name="Rivoluzione_15" type="continuous">
    <origin xyz="-0.001813 0.000846 0.0" rpy="0 0 0"/>
    <parent link="perno_FL_1"/>
    <child link="tyre_FL_1"/>
    <axis xyz="-0.906308 0.422618 0.0"/>
  </joint>

  <joint name="Rivoluzione_16" type="revolute">
    <origin xyz="0.1355 0.0 0.0" rpy="0 0 0"/>
    <parent link="link_FR_1"/>
    <child link="perno_FR_1"/>
    <axis xyz="0.0 -0.0 1.0"/>
    <limit upper="0.523599" lower="-0.523599" effort="100" velocity="100"/>
  </joint>

  <joint name="Rivoluzione_17" type="continuous">
    <origin xyz="0.001812 -0.000845 0.0" rpy="0 0 0"/>
    <parent link="perno_FR_1"/>
    <child link="tyre_FR_1"/>
    <axis xyz="0.906308 -0.422618 -0.0"/>
  </joint>

  <joint name="Rivoluzione_20" type="continuous">
    <origin xyz="0.134567 0.0 0.0" rpy="0 0 0"/>
    <parent link="link_RR_1"/>
    <child link="tyre_RR_1"/>
    <axis xyz="1.0 0.0 -0.0"/>
  </joint>

  <joint name="Rigido_21" type="fixed">
    <origin xyz="-0.095283 -0.293131 1.6e-05" rpy="0 0 0"/>
    <parent link="chassis"/>
    <child link="link_RL_1"/>
  </joint>

  <joint name="Rigido_22" type="fixed">
    <origin xyz="-0.015283 -0.293131 1.6e-05" rpy="0 0 0"/>
    <parent link="chassis"/>
    <child link="link_RR_1"/>
  </joint>

  <joint name="Rivoluzione_23" type="continuous">
    <origin xyz="-0.134568 0.0 0.0" rpy="0 0 0"/>
    <parent link="link_RL_1"/>
    <child link="tyre_RL_1"/>
    <axis xyz="-1.0 -0.0 0.0"/>
  </joint>

  <joint name="Rigido_24" type="fixed">
    <origin xyz="-0.095283 0.306869 1.6e-05" rpy="0 0 0"/>
    <parent link="chassis"/>
    <child link="link_FL_1"/>
  </joint>

  <joint name="Rigido_25" type="fixed">
    <origin xyz="-0.015283 0.306869 1.6e-05" rpy="0 0 0"/>
    <parent link="chassis"/>
    <child link="link_FR_1"/>
  </joint>


<link name="imu_link">
  <visual>
    <geometry>
      <box size="0.1 0.1 0.1"/>
    </geometry>
  </visual>

  <collision>
    <geometry>
      <box size="0.1 0.1 0.1"/>
    </geometry>
  </collision>

  <!-- <xacro:box_inertia m="0.1" w="0.1" d="0.1" h="0.1"/> -->
</link>

<joint name="imu_joint" type="fixed">
  <parent link="chassis"/>
  <child link="imu_link"/>
  <origin xyz="0 0 1"/>
</joint>

 <gazebo reference="imu_link">
  <sensor name="imu_sensor" type="imu">
   <plugin filename="libgazebo_ros_imu_sensor.so" name="imu_plugin">
      <ros>
        <namespace>/demo</namespace>
        <remapping>~/out:=imu</remapping>
      </ros>
      <initial_orientation_as_reference>false</initial_orientation_as_reference>
    </plugin>
    <always_on>true</always_on>
    <update_rate>100</update_rate>
    <visualize>true</visualize>
    <imu>
      <angular_velocity>
        <x>
          <noise type="gaussian">
            <mean>0.0</mean>
            <stddev>2e-4</stddev>
            <bias_mean>0.0000075</bias_mean>
            <bias_stddev>0.0000008</bias_stddev>
          </noise>
        </x>
        <y>
          <noise type="gaussian">
            <mean>0.0</mean>
            <stddev>2e-4</stddev>
            <bias_mean>0.0000075</bias_mean>
            <bias_stddev>0.0000008</bias_stddev>
          </noise>
        </y>
        <z>
          <noise type="gaussian">
            <mean>0.0</mean>
            <stddev>2e-4</stddev>
            <bias_mean>0.0000075</bias_mean>
            <bias_stddev>0.0000008</bias_stddev>
          </noise>
        </z>
      </angular_velocity>
      <linear_acceleration>
        <x>
          <noise type="gaussian">
            <mean>0.0</mean>
            <stddev>1.7e-2</stddev>
            <bias_mean>0.1</bias_mean>
            <bias_stddev>0.001</bias_stddev>
          </noise>
        </x>
        <y>
          <noise type="gaussian">
            <mean>0.0</mean>
            <stddev>1.7e-2</stddev>
            <bias_mean>0.1</bias_mean>
            <bias_stddev>0.001</bias_stddev>
          </noise>
        </y>
        <z>
          <noise type="gaussian">
            <mean>0.0</mean>
            <stddev>1.7e-2</stddev>
            <bias_mean>0.1</bias_mean>
            <bias_stddev>0.001</bias_stddev>
          </noise>
        </z>
      </linear_acceleration>
    </imu>
  </sensor>
</gazebo>

<gazebo>
  <plugin name='diff_drive' filename='libgazebo_ros_diff_drive.so'>
    <ros>
      <namespace>/demo</namespace>
    </ros>

    <!-- wheels -->
    <left_joint>Rivoluzione_23</left_joint>
    <right_joint>Rivoluzione_20</right_joint>

    <!-- kinematics -->
    <wheel_separation>0.35</wheel_separation>
    <wheel_diameter>0.19</wheel_diameter>

    <!-- limits -->
    <max_wheel_torque>20</max_wheel_torque>
    <max_wheel_acceleration>1.0</max_wheel_acceleration>

    <!-- output -->
    <publish_odom>true</publish_odom>
    <publish_odom_tf>false</publish_odom_tf>
    <publish_wheel_tf>true</publish_wheel_tf>

    <odometry_frame>odom</odometry_frame>
    <robot_base_frame>base_link</robot_base_frame>
  </plugin>
</gazebo>


</robot>
